Workbook

Sheet readme
B2: Total unique relationship | C2: where the other party is private | D2: with an scf match
B3: =COUNTIF(doublecounting!C3:D3579,">0")-SUM(doublecounting!E3:E3579) -> 3577 | D3: =COUNTIF(doublecounting!F3:G3579,">0")-SUM(doublecounting!H3:H3579) -> 980
B4: of which in target file
B5: =COUNTIF(doublecounting!C3:C3579,">0") -> 1932 | D5: =COUNTIF(doublecounting!F3:F3579,">0") -> 730
B6: of which in source file
B7: =COUNTIF(doublecounting!D3:D3579,">0") -> 1680 | D7: =COUNTIF(doublecounting!G3:G3579,">0") -> 256
B8: of which in both
B9: =SUM(doublecounting!E3:E3579) -> 35 | D9: =SUM(doublecounting!H3:H3579) -> 6
B10: ratio suppliers per buyer
B11: =readme!B3/COUNTA(has_scf!$E$2:$E$1366) -> 2.6205128 | D11: =readme!D3/COUNTIF(has_scf!F2:F1366,">0") -> 10

Sheet has_scf
A1: filing_id | B1: isin | C1: has_scf | E1: unique_isin
A2: 7742710 | B2: GB00B65TLW28 | C2: 0 | E2: GB00B65TLW28 | F2: =COUNTIFS($B$2:$B$40260,E2,$C$2:$C$40260,1) -> 0
A3: 7741925 | B3: GB00BLTVCF91 | C3: 0 | E3: GB00BLTVCF91 | F3: =COUNTIFS($B$2:$B$40260,E3,$C$2:$C$40260,1) -> 0
A4: 7741924 | B4: GB00BNDQJN14 | C4: 0 | E4: GB00BNDQJN14 | F4: =COUNTIFS($B$2:$B$40260,E4,$C$2:$C$40260,1) -> 0
A5: 7741923 | B5: GB00BYQ0JC66 | C5: 0 | E5: GB00BYQ0JC66 | F5: =COUNTIFS($B$2:$B$40260,E5,$C$2:$C$40260,1) -> 0
A6: 7741910 | B6: GB00BYX7MG58 | C6: 0 | E6: GB00BYX7MG58 | F6: =COUNTIFS($B$2:$B$40260,E6,$C$2:$C$40260,1) -> 0
A7: 7741888 | B7: GB0004270301 | C7: 0 | E7: GB0004270301 | F7: =COUNTIFS($B$2:$B$40260,E7,$C$2:$C$40260,1) -> 0
A8: 7741887 | B8: GB0000961622 | C8: 0 | E8: GB0000961622 | F8: =COUNTIFS($B$2:$B$40260,E8,$C$2:$C$40260,1) -> 1
A9: 7741886 | B9: GB0006825383 | C9: 0 | E9: GB0006825383 | F9: =COUNTIFS($B$2:$B$40260,E9,$C$2:$C$40260,1) -> 0
A10: 7741818 | B10: GB00BMDV1220 | C10: 0 | E10: GB00BMDV1220 | F10: =COUNTIFS($B$2:$B$40260,E10,$C$2:$C$40260,1) -> 1
A11: 7741810 | B11: GB00B45XLP34 | C11: 0 | E11: GB00B45XLP34 | F11: =COUNTIFS($B$2:$B$40260,E11,$C$2:$C$40260,1) -> 0
A12: 7741796 | B12: GB00B65TLW28 | C12: 0 | E12: GB00BDFGHW41 | F12: =COUNTIFS($B$2:$B$40260,E12,$C$2:$C$40260,1) -> 0
A13: 7740575 | B13: GB00BDFGHW41 | C13: 0 | E13: VGG368811037 | F13: =COUNTIFS($B$2:$B$40260,E13,$C$2:$C$40260,1) -> 0
... A1366: 6770498 | B1366: GB00BLR8L223 | C1366: 0 | E1366: GB00B01YQ796 | F1366: =COUNTIFS($B$2:$B$40260,E1366,$C$2:$C$40260,1) -> 0
A1367: 6770491 | B1367: GB0030181522 | C1367: 0
A1368: 6770484 | B1368: GB00B0358N07 | C1368: 0
A1369: 6770475 | B1369: GB0032089863 | C1369: 0
A1370: 6770470 | B1370: GB00B1VNSX38 | C1370: 0
A1371: 6770469 | B1371: GB00B00FPT80 | C1371: 0
A1372: 6770462 | B1372: GB0007922338 | C1372: 0
A1373: 6770459 | B1373: GB00BMD6PM55 | C1373: 0
A1374: 6770449 | B1374: GB00B8YZTJ80 | C1374: 0
A1375: 6770447 | B1375: GB0009580571 | C1375: 0
A1376: 6770436 | B1376: GB00BG0X1P77 | C1376: 0
A1377: 6770413 | B1377: GB0003062816 | C1377: 0
A1378: 5672330 | B1378: GB00BFYYT831 | C1378: 0
... A40260: 3201688 | B40260: GB00B0CJ9K73 | C40260: 0

Sheet target_uk
A1: rel_type | B1: column_4_doublecounting | C1: target_isin | D1: has_scf | E1: start_ | F1: id | G1: source_company_id | H1: target_company_id | I1: subsidiaries | J1: revenue_percent | K1: percent_estimated | L1: source_company_subsidiaries | M1: target_company_subsidiaries | N1: source_name | O1: source_ticker | P1: source_cusip | Q1: source_isin | R1: source_sedol | S1: target_name | T1: target_ticker | U1: target_cusip | V1: target_sedol | W1: source_company_keyword | X1: target_company_keyword | Y1: keyword1 | Z1: keyword2 | AA1: keyword3 | AB1: keyword4 | AC1: keyword5 | AD1: keyword6 | AE1: keyword7 | AF1: keyword8 | AG1: keyword9 | AH1: keyword10 | AI1: end_
A2: CUSTOMER | B2: =C2&IF(Q2="",W2,Q2) -> GB00BK9RKT01SE0000407991 | C2: GB00BK9RKT01 | D2: =SIGN(VLOOKUP(target_uk!C2,has_scf!$E$2:$F$1366,2,FALSE)) -> 1 | E2: 42709 | F2: CUST-101223503 | G2: 194503174 | H2: 1776804 | K2: Y | M2: City plumbing Supplies Holdings Ltd | N2: Svedbergs Group AB | O2: SVED.B | P2: W89736115 | Q2: SE0000407991 | R2: B12Z0T8 | S2: Travis Perkins Plc | T2: TPK | U2: G90202139 | V2: BK9RKT0 | W2: Svedbergs I Dalstorp | X2: City plumbing Supplies | AI2: 43963
A3: CUSTOMER | B3: =C3&IF(Q3="",W3,Q3) -> GB00BK9RKT01SE0000407991 | C3: GB00BK9RKT01 | D3: =SIGN(VLOOKUP(target_uk!C3,has_scf!$E$2:$F$1366,2,FALSE)) -> 1 | E3: 43963 | F3: CUST-101223503 | G3: 194503174 | H3: 1776804 | K3: Y | M3: City Plumbing Supplies Holdings Ltd | N3: Svedbergs Group AB | O3: SVED.B | P3: W89736115 | Q3: SE0000407991 | R3: B12Z0T8 | S3: Travis Perkins Plc | T3: TPK | U3: G90202139 | V3: BK9RKT0 | W3: Svedbergs I Dalstorp | X3: City plumbing Supplies | AI3: 44365
A4: CUSTOMER | B4: =C4&IF(Q4="",W4,Q4) -> GB00B3MBS747US84763R1014 | C4: GB00B3MBS747 | D4: =SIGN(VLOOKUP(target_uk!C4,has_scf!$E$2:$F$1366,2,FALSE)) -> 0 | E4: 42710 | F4: CUST-101300131 | G4: 8594 | H4: 194520295 | K4: Y | N4: Spectrum Brands Legacy, Inc. | O4: SPB.XX1 | P4: 84763R101 | Q4: US84763R1014 | R4: B3MYPN8 | S4: Ocado Group Plc | T4: OCDO | U4: G6718L106 | V4: B3MBS74 | W4: Spectrum Brands | X4: Ocado Group | Y4: Scale and Distribution | Z4: Europe | AI4: 767011
A5: CUSTOMER | B5: =C5&IF(Q5="",W5,Q5) -> GB00B012TP20US84763R1014 | C5: GB00B012TP20 | D5: =SIGN(VLOOKUP(target_uk!C5,has_scf!$E$2:$F$1366,2,FALSE)) -> 0 | E5: 42710 | F5: CUST-101300417 | G5: 8594 | H5: 1832300 | K5: Y | N5: Spectrum Brands Legacy, Inc. | O5: SPB.XX1 | P5: 84763R101 | Q5: US84763R1014 | R5: B3MYPN8 | S5: Halfords Group Plc | T5: HFD | U5: G4280E105 | V5: B012TP2 | W5: Spectrum Brands | X5: Halfords Group | Y5: Scale and Distribution | Z5: Europe | AI5: 767011
A6: CUSTOMER | B6: =C6&IF(Q6="",W6,Q6) -> GB00BRJQ8J25GB0009422543 | C6: GB00BRJQ8J25 | D6: =SIGN(VLOOKUP(target_uk!C6,has_scf!$E$2:$F$1366,2,FALSE)) -> 0 | E6: 42710 | F6: CUST-101320503 | G6: 1832545 | H6: 1832308 | K6: Y | N6: Waterman Group Plc | O6: WTM | P6: G94755108 | Q6: GB0009422543 | R6: 942254 | S6: Hammerson Plc | T6: HMSO | U6: G4273Q206 | V6: BRJQ8J2 | W6: Waterman Group | X6: Hammerson | Y6: structural | Z6: developer | AI6: 45583
A7: CUSTOMER | B7: =C7&IF(Q7="",W7,Q7) -> GB00B0744B38US6097201072 | C7: GB00B0744B38 | D7: =SIGN(VLOOKUP(target_uk!C7,has_scf!$E$2:$F$1366,2,FALSE)) -> 0 | E7: 42716 | F7: CUST-101524843 | G7: 6928 | H7: 1302 | K7: Y | M7: Bunzl Distribution Midcentral, Inc | N7: Monmouth Real Estate Investment Corp. | O7: MNR.XX10 | P7: 609720107 | Q7: US6097201072 | R7: 2504072 | S7: Bunzl Plc | T7: BNZL | U7: G16968110 | V7: B0744B3 | W7: Monmouth | X7: Bunzl Distribution Midcentral, Inc | Y7: Principal Tenants | AI7: 44171
A8: CUSTOMER | B8: =C8&IF(Q8="",W8,Q8) -> GB00B0744B38US6097201072 | C8: GB00B0744B38 | D8: =SIGN(VLOOKUP(target_uk!C8,has_scf!$E$2:$F$1366,2,FALSE)) -> 0 | E8: 44171 | F8: CUST-101524843 | G8: 6928 | H8: 1302 | J8: 0.46 | K8: Y | M8: Bunzl Distribution Midcentral, Inc | N8: Monmouth Real Estate Investment Corp. | O8: MNR.XX10 | P8: 609720107 | Q8: US6097201072 | R8: 2504072 | S8: Bunzl Plc | T8: BNZL | U8: G16968110 | V8: B0744B3 | W8: Monmouth | X8: Bunzl Distribution Midcentral, Inc | Y8: Principal Tenants | AI8: 44572
A9: CUSTOMER | B9: =C9&IF(Q9="",W9,Q9) -> GB00B1L5QH97MT0000780107 | C9: GB00B1L5QH97 | D9: =SIGN(VLOOKUP(target_uk!C9,has_scf!$E$2:$F$1366,2,FALSE)) -> 0 | E9: 43598 | F9: CUST-101588699 | G9: 16087650 | H9: 16033 | K9: Y | M9: Grosvenor Casinos Ltd. | N9: Kambi Group Plc | O9: KAMBI | P9: X4170A107 | Q9: MT0000780107 | R9: BMNQDC1 | S9: Rank Group Plc | T9: RNK | U9: G7377H121 | V9: B1L5QH9 | W9: kambi group plc | X9: Rank Group | AI9: 43969
A10: CUSTOMER | B10: =C10&IF(Q10="",W10,Q10) -> GB00B1L5QH97MT0000780107 | C10: GB00B1L5QH97 | D10: =SIGN(VLOOKUP(target_uk!C10,has_scf!$E$2:$F$1366,2,FALSE)) -> 0 | E10: 43969 | F10: CUST-101588699 | G10: 16087650 | H10: 16033 | K10: Y | N10: Kambi Group Plc | O10: KAMBI | P10: X4170A107 | Q10: MT0000780107 | R10: BMNQDC1 | S10: Rank Group Plc | T10: RNK | U10: G7377H121 | V10: B1L5QH9 | W10: kambi group plc | X10: Rank Group | AI10: 44282
A11: CUSTOMER | B11: =C11&IF(Q11="",W11,Q11) -> GB0031274896LK0080N00008 | C11: GB0031274896 | D11: =SIGN(VLOOKUP(target_uk!C11,has_scf!$E$2:$F$1366,2,FALSE)) -> 1 | E11: 42717 | F11: CUST-101606479 | G11: 22437286 | H11: 1603503 | K11: Y | L11: Hayleys Fabric | N11: Hayleys Plc | O11: HAYL.N0000 | P11: Y3117K102 | Q11: LK0080N00008 | R11: 6416054 | S11: Marks & Spencer Group Plc | T11: MKS | U11: G5824M107 | V11: 3127489 | W11: Hayleys Fabric | X11: Marks & Spencer | Y11: fabric | AI11: 44132
A12: CUSTOMER | B12: =C12&IF(Q12="",W12,Q12) -> GB0031274896LK0080N00008 | C12: GB0031274896 | D12: =SIGN(VLOOKUP(target_uk!C12,has_scf!$E$2:$F$1366,2,FALSE)) -> 1 | E12: 44132 | F12: CUST-101606479 | G12: 22437286 | H12: 1603503 | K12: Y | L12: Hayleys Fabric | N12: Hayleys Plc | O12: HAYL.N0000 | P12: Y3117K102 | Q12: LK0080N00008 | R12: 6416054 | S12: Marks & Spencer Group Plc | T12: MKS | U12: G5824M107 | V12: 3127489 | W12: Hayleys Fabric | X12: Marks & Spencer | Y12: fabric | AI12: 44132
A13: CUSTOMER | B13: =C13&IF(Q13="",W13,Q13) -> GB0032089863LK0080N00008 | C13: GB0032089863 | D13: =SIGN(VLOOKUP(target_uk!C13,has_scf!$E$2:$F$1366,2,FALSE)) -> 0 | E13: 42717 | F13: CUST-101607911 | G13: 22437286 | H13: 1516749 | K13: Y | L13: Hayleys Fabric | N13: Hayleys Plc | O13: HAYL.N0000 | P13: Y3117K102 | Q13: LK0080N00008 | R13: 6416054 | S13: Next Plc | T13: NXT | U13: G6500M106 | V13: 3208986 | W13: Hayleys Fabric | X13: NEXT | Y13: fabric | AI13: 44132
A14: CUSTOMER | B14: =C14&IF(Q14="",W14,Q14) -> GB0032089863LK0080N00008 | C14: GB0032089863 | D14: =SIGN(VLOOKUP(target_uk!C14,has_scf!$E$2:$F$1366,2,FALSE)) -> 0 | E14: 44132 | F14: CUST-101607911 | G14: 22437286 | H14: 1516749 | K14: Y | L14: Hayleys Fabric | N14: Hayleys Plc | O14: HAYL.N0000 | P14: Y3117K102 | Q14: LK0080N00008 | R14: 6416054 | S14: Next Plc | T14: NXT | U14: G6500M106 | V14: 3208986 | W14: Hayleys Fabric | X14: NEXT | Y14: fabric | AI14: 44132
A15: CUSTOMER | B15: =C15&IF(Q15="",W15,Q15) -> GB00B63H8491NO0003064107 | C15: GB00B63H8491 | D15: =SIGN(VLOOKUP(target_uk!C15,has_scf!$E$2:$F$1366,2,FALSE)) -> 1 | E15: 42717 | F15: CUST-101616619 | G15: 194502501 | H15: 240030 | K15: Y | N15: Data Respons AS (Norway) | O15: DAT | P15: R4548G106 | Q15: NO0003064107 | R15: 5195279 | S15: Rolls-Royce Holdings Plc | T15: RR | U15: G76225104 | V15: B63H849 | W15: Data Respons | X15: Rolls-Royce | Y15: global companies | AI15: 44780
A16: CUSTOMER | B16: =C16&IF(Q16="",W16,Q16) -> GB0007325078L. G. Balakrishnan & Brothers | C16: GB0007325078 | D16: =SIGN(VLOOKUP(target_uk!C16,has_scf!$E$2:$F$1366,2,FALSE)) -> 0 | E16: 43379 | F16: CUST-104140497 | G16: 22451503 | H16: 1832454 | K16: Y | M16: Renold Chain India Pvt Ltd | S16: Renold Plc | T16: RNO | U16: G75035108 | V16: 732507 | W16: L. G. Balakrishnan & Brothers | X16: Renold Chain India | AI16: 44140
A17: CUSTOMER | B17: =C17&IF(Q17="",W17,Q17) -> GB0007325078L. G. Balakrishnan & Brothers | C17: GB0007325078 | D17: =SIGN(VLOOKUP(target_uk!C17,has_scf!$E$2:$F$1366,2,FALSE)) -> 0 | E17: 44140 | F17: CUST-104140497 | G17: 22451503 | H17: 1832454 | J17: 0.2 | K17: Y | M17: Renold Chain India Pvt Ltd | S17: Renold Plc | T17: RNO | U17: G75035108 | V17: 732507 | W17: L. G. Balakrishnan & Brothers | X17: Renold Chain India | AI17: 44421
A18: CUSTOMER | B18: =C18&IF(Q18="",W18,Q18) -> GB00BJVH7905Summit Utica | C18: GB00BJVH7905 | D18: =SIGN(VLOOKUP(target_uk!C18,has_scf!$E$2:$F$1366,2,FALSE)) -> 0 | E18: 43542 | F18: CUST-106431549 | G18: 194531900 | H18: 194517589 | K18: Y | L18: Summit Midstream Utica, LLC | M18: Ascent Resources â€“ Utica LLC | N18: Summit Midstream Partners LP | P18: FDS0AL6O1 | S18: Ascent Resources Plc | T18: AST | U18: G05944122 | V18: BJVH790 | W18: Summit Utica | X18: Ascent Resources â€“ Utica LLC | Y18: Utica Shale | AI18: 44319
A19: CUSTOMER | B19: =C19&IF(Q19="",W19,Q19) -> GB0007188757CLP6877L1036 | C19: GB0007188757 | D19: =SIGN(VLOOKUP(target_uk!C19,has_scf!$E$2:$F$1366,2,FALSE)) -> 1 | E19: 43746 | F19: CUST-106477035 | G19: 21070353 | H19: 8792 | K19: Y | M19: Kennecott Molybdenum Company | N19: Molibdenos y Metales SA | O19: MOLYMET | P19: P6877L103 | Q19: CLP6877L1036 | R19: 2543837 | S19: Rio Tinto Plc | T19: RIO | U19: G75754104 | V19: 718875 | W19: Molymet | X19: Kennecott | Y19: Tolling | AI19: 45219
A20: CUSTOMER | B20: =C20&IF(Q20="",W20,Q20) -> GB0033195214TRETRGY00018 | C20: GB0033195214 | D20: =SIGN(VLOOKUP(target_uk!C20,has_scf!$E$2:$F$1366,2,FALSE)) -> 1 | E20: 43566 | F20: CUST-108436577 | G20: 194524064 | H20: 218393 | J20: 1.3 | K20: Y | M20: Koctas Yapi Marketleri Ticaret A.S. | N20: Torunlar Gayrimenkul Yatirim Ortakligi AS | O20: TRGYO.E | P20: M8820E106 | Q20: TRETRGY00018 | R20: B4WW142 | S20: Kingfisher plc | T20: KGF | U20: G5256E441 | V20: 3319521 | W20: Torunlar Gayrimenkul Yatirim Ortakligi | X20: Koctas Yapi Marketleri Ticaret A.S. | Y20: top 10 tenants | AI20: 43973
A21: CUSTOMER | B21: =C21&IF(Q21="",W21,Q21) -> GB0033195214TRETRGY00018 | C21: GB0033195214 | D21: =SIGN(VLOOKUP(target_uk!C21,has_scf!$E$2:$F$1366,2,FALSE)) -> 1 | E21: 43973 | F21: CUST-108436577 | G21: 194524064 | H21: 218393 | J21: 1.3 | K21: Y | M21: Koctas Yapi Marketleri Ticaret A.S. | N21: Torunlar Gayrimenkul Yatirim Ortakligi AS | O21: TRGYO.E | P21: M8820E106 | Q21: TRETRGY00018 | R21: B4WW142 | S21: Kingfisher plc | T21: KGF | U21: G5256E441 | V21: 3319521 | W21: Torunlar Gayrimenkul Yatirim Ortakligi | X21: Koctas Yapi Marketleri Ticaret A.S. | Y21: top 10 tenants | AI21: 43973
A22: CUSTOMER | B22: =C22&IF(Q22="",W22,Q22) -> NL0010545661CNE100000F79 | C22: NL0010545661 | D22: =SIGN(VLOOKUP(target_uk!C22,has_scf!$E$2:$F$1366,2,FALSE)) -> 0 | E22: 43399 | F22: CUST-108718518 | G22: 20706105 | H22: 194536706 | K22: Y | M22: IVECO S.p.A. | N22: Tianrun Industry Technology Co., Ltd. | O22: 2283 | P22: Y8817C102 | Q22: CNE100000F79 | R22: B3YKH94 | S22: CNH Industrial NV | T22: CNH | U22: N20944109 | V22: BDX85Z1 | W22: Tianrun Crankshaft | X22: Iveco | Y22: SAIC-IVECO Commercial Vehicle Investing Co., Ltd. | Z22: crankshaft | AA22: Connecting rods | AB22: Saic Fiat Powertrain Hongyan Co., Ltd. | AI22: 767011
A23: CUSTOMER | B23: =C23&IF(Q23="",W23,Q23) -> GB00B7KR2P84CH0319416936 | C23: GB00B7KR2P84 | D23: =SIGN(VLOOKUP(target_uk!C23,has_scf!$E$2:$F$1366,2,FALSE)) -> 0 | E23: 42872 | F23: CUST-108783614 | G23: 22443919 | H23: 1634656 | K23: Y | N23: Flughafen ZÃ¼rich AG | O23: FHZN | P23: H26552135 | Q23: CH0319416936 | R23: BYQ8481 | S23: easyJet Plc | T23: EZJ | U23: G3030S109 | V23: B7KR2P8 | W23: Flughafen Zuerich | X23: easyJet | Y23: Airlines | AI23: 767011
A24: CUSTOMER | B24: =C24&IF(Q24="",W24,Q24) -> NL0010545661IL0010827348 | C24: NL0010545661 | D24: =SIGN(VLOOKUP(target_uk!C24,has_scf!$E$2:$F$1366,2,FALSE)) -> 0 | E24: 42926 | F24: CUST-110898171 | G24: 249309 | H24: 194536706 | K24: Y | N24: Top Image Systems Ltd. | O24: TISA | P24: M87896102 | Q24: IL0010827348 | R24: 2896520 | S24: CNH Industrial NV | T24: CNH | U24: N20944109 | V24: BDX85Z1 | W24: Top Image Systems | X24: CNH Industrial | Y24: document processing solutions | AI24: 767011
A25: CUSTOMER | B25: =C25&IF(Q25="",W25,Q25) -> GB00B63H8491DE000A2DAM03 | C25: GB00B63H8491 | D25: =SIGN(VLOOKUP(target_uk!C25,has_scf!$E$2:$F$1366,2,FALSE)) -> 1 | E25: 42944 | F25: CUST-111068936 | G25: 103256861 | H25: 240030 | K25: Y | N25: Aumann AG | O25: AAG | P25: D0R9AW106 | Q25: DE000A2DAM03 | R25: BYW82K3 | S25: Rolls-Royce Holdings Plc | T25: RR | U25: G76225104 | V25: B63H849 | W25: aumann ag | X25: Rolls-Royce | Y25: classic | AI25: 44701
A26: CUSTOMER | B26: =C26&IF(Q26="",W26,Q26) -> GB00BMBVGQ36GB00B5N0P849 | C26: GB00BMBVGQ36 | D26: =SIGN(VLOOKUP(target_uk!C26,has_scf!$E$2:$F$1366,2,FALSE)) -> 1 | E26: 42929 | F26: CUST-111076104 | G26: 1587136 | H26: 8264 | K26: Y | N26: John Wood Group Plc | O26: WG | P26: G9745T118 | Q26: GB00B5N0P849 | R26: B5N0P84 | S26: Harbour Energy Plc | T26: HBR | U26: G4289T111 | V26: BMBVGQ3 | W26: John Wood | X26: Premier Oil | Y26: front end engineering design | Z26: topsides | AA26: jacket | AB26: pipeline | AC26: flow assurance | AD26: subsea engineering | AE26: Tolmount offshore field | AF26: Southern North Sea | AI26: 43938
A27: CUSTOMER | B27: =C27&IF(Q27="",W27,Q27) -> GB00BMBVGQ36GB00B5N0P849 | C27: GB00BMBVGQ36 | D27: =SIGN(VLOOKUP(target_uk!C27,has_scf!$E$2:$F$1366,2,FALSE)) -> 1 | E27: 43938 | F27: CUST-111076104 | G27: 1587136 | H27: 8264 | K27: Y | N27: John Wood Group Plc | O27: WG | P27: G9745T118 | Q27: GB00B5N0P849 | R27: B5N0P84 | S27: Harbour Energy Plc | T27: HBR | U27: G4289T111 | V27: BMBVGQ3 | W27: John Wood | X27: Premier Oil | Y27: front end engineering design | Z27: topsides | AA27: jacket | AB27: pipeline | AC27: flow assurance | AD27: subsea engineering | AE27: Tolmount offshore field | AF27: Southern North Sea | AI27: 43938
A28: CUSTOMER | B28: =C28&IF(Q28="",W28,Q28) -> GB0005603997AU000000BVS9 | C28: GB0005603997 | D28: =SIGN(VLOOKUP(target_uk!C28,has_scf!$E$2:$F$1366,2,FALSE)) -> 0 | E28: 42929 | F28: CUST-111136388 | G28: 22246309 | H28: 1402018 | K28: Y | N28: Bravura Solutions Ltd. | O28: BVS | P28: Q17548167 | Q28: AU000000BVS9 | R28: BZBHBM3 | S28: Legal & General Group Plc | T28: LGEN | U28: G54404127 | V28: 560399 | W28: Bravura Solutions | X28: Legal & General | Y28: financial solutions | AI28: 44780
A29: CUSTOMER | B29: =C29&IF(Q29="",W29,Q29) -> GB00BP9LHF23AU000000BVS9 | C29: GB00BP9LHF23 | D29: =SIGN(VLOOKUP(target_uk!C29,has_scf!$E$2:$F$1366,2,FALSE)) -> 0 | E29: 42929 | F29: CUST-111136426 | G29: 22246309 | H29: 1732173 | K29: Y | N29: Bravura Solutions Ltd. | O29: BVS | P29: Q17548167 | Q29: AU000000BVS9 | R29: BZBHBM3 | S29: Schroders Plc | T29: SDR | U29: G78602144 | V29: BP9LHF2 | W29: Bravura Solutions | X29: Schroders | Y29: financial solutions | AI29: 45168
A30: CUSTOMER | B30: =C30&IF(Q30="",W30,Q30) -> GB00B63H8491US0048482063 | C30: GB00B63H8491 | D30: =SIGN(VLOOKUP(target_uk!C30,has_scf!$E$2:$F$1366,2,FALSE)) -> 1 | E30: 42930 | F30: CUST-111170190 | G30: 3001 | H30: 240030 | K30: Y | L30: OmniMetrix, LLC | M30: MTU Onsite Energy | N30: Acorn Energy, Inc. | O30: ACFN | P30: 4848206 | Q30: US0048482063 | R30: BQBBF53 | S30: Rolls-Royce Holdings Plc | T30: RR | U30: G76225104 | V30: B63H849 | W30: OmniMetrix | X30: MTU Solutions | Y30: PG monitors | AI30: 43943
A31: CUSTOMER | B31: =C31&IF(Q31="",W31,Q31) -> GB00B63H8491US0048482063 | C31: GB00B63H8491 | D31: =SIGN(VLOOKUP(target_uk!C31,has_scf!$E$2:$F$1366,2,FALSE)) -> 1 | E31: 43943 | F31: CUST-111170190 | G31: 3001 | H31: 240030 | K31: Y | L31: OmniMetrix, LLC | M31: MTU Energy | N31: Acorn Energy, Inc. | O31: ACFN | P31: 4848206 | Q31: US0048482063 | R31: BQBBF53 | S31: Rolls-Royce Holdings Plc | T31: RR | U31: G76225104 | V31: B63H849 | W31: OmniMetrix | X31: MTU Solutions | Y31: PG monitors | AI31: 44780
A32: CUSTOMER | B32: =C32&IF(Q32="",W32,Q32) -> GB0033195214US0296831094 | C32: GB0033195214 | D32: =SIGN(VLOOKUP(target_uk!C32,has_scf!$E$2:$F$1366,2,FALSE)) -> 1 | E32: 42984 | F32: CUST-113126290 | G32: 611 | H32: 218393 | K32: Y | M32: Screwfix Direct Ltd. | N32: Logility Supply Chain Solutions, Inc. | O32: LGTY | P32: 29683109 | Q32: US0296831094 | R32: 2029575 | S32: Kingfisher plc | T32: KGF | U32: G5256E441 | V32: 3319521 | W32: American Software | X32: Screwfix | Y32: Software Solutions | Z32: Wholesale distribution | AI32: 767011
A33: CUSTOMER | B33: =C33&IF(Q33="",W33,Q33) -> GB0006215205US2506601077 | C33: GB0006215205 | D33: =SIGN(VLOOKUP(target_uk!C33,has_scf!$E$2:$F$1366,2,FALSE)) -> 1 | E33: 42984 | F33: CUST-113164239 | G33: 80724223 | H33: 1606358 | K33: Y | M33: c2c Rail Ltd. | N33: Determine, Inc. | O33: DTRM | P33: 250660107 | Q33: US2506601077 | R33: BYNK9L8 | S33: Mobico Group Plc | T33: MCG | U33: G6374M109 | V33: 621520 | W33: Determine | X33: c2c | Y33: Determine Cloud Platform | AI33: 43836
A34: CUSTOMER | B34: =C34&IF(Q34="",W34,Q34) -> GB0006215205US2506601077 | C34: GB0006215205 | D34: =SIGN(VLOOKUP(target_uk!C34,has_scf!$E$2:$F$1366,2,FALSE)) -> 1 | E34: 43836 | F34: CUST-113164239 | G34: 80724223 | H34: 1606358 | K34: Y | M34: c2c Rail Ltd. | N34: Determine, Inc. | O34: DTRM | P34: 250660107 | Q34: US2506601077 | R34: BYNK9L8 | S34: Mobico Group Plc | T34: MCG | U34: G6374M109 | V34: 621520 | W34: Determine | X34: c2c | Y34: Determine Cloud Platform | AI34: 43836
A35: CUSTOMER | B35: =C35&IF(Q35="",W35,Q35) -> GB00BNLPYF73US24661P8077 | C35: GB00BNLPYF73 | D35: =SIGN(VLOOKUP(target_uk!C35,has_scf!$E$2:$F$1366,2,FALSE)) -> 0 | E35: 42984 | F35: CUST-113177424 | G35: 248227 | H35: 63440346 | K35: Y | M35: Spire Southampton Hospital | N35: Delcath Systems, Inc. | O35: DCTH | P35: 24661P807 | Q35: US24661P8077 | R35: BK228T8 | S35: Spire Healthcare Group Plc | T35: SPI | U35: G83577109 | V35: BNLPYF7 | W35: Delcath Systems | X35: Spire Southampton Hospital | Y35: percutaneous hepatic perfusion | Z35: PHP | AA35: CHEMOSTAT | AB35: Melphalan/HDS | AC35: whole organ therapy | AD35: liver | AE35: Europe | AI35: 43872
A36: CUSTOMER | B36: =C36&IF(Q36="",W36,Q36) -> GB00BNLPYF73US24661P8077 | C36: GB00BNLPYF73 | D36: =SIGN(VLOOKUP(target_uk!C36,has_scf!$E$2:$F$1366,2,FALSE)) -> 0 | E36: 43872 | F36: CUST-113177424 | G36: 248227 | H36: 63440346 | K36: Y | M36: Spire Southampton Hospital | N36: Delcath Systems, Inc. | O36: DCTH | P36: 24661P807 | Q36: US24661P8077 | R36: BK228T8 | S36: Spire Healthcare Group Plc | T36: SPI | U36: G83577109 | V36: BNLPYF7 | W36: Delcath Systems | X36: Spire Southampton Hospital | Y36: percutaneous hepatic perfusion | Z36: PHP | AA36: CHEMOSTAT | AB36: Melphalan/HDS | AC36: whole organ therapy | AD36: liver | AE36: Europe | AI36: 43872
A37: CUSTOMER | B37: =C37&IF(Q37="",W37,Q37) -> GB00BMWC6P49AT000AGRANA3 | C37: GB00BMWC6P49 | D37: =SIGN(VLOOKUP(target_uk!C37,has_scf!$E$2:$F$1366,2,FALSE)) -> 0 | E37: 42986 | F37: CUST-113263455 | G37: 194502681 | H37: 1921554 | K37: Y | N37: AGRANA Beteiligungs-AG | O37: AGR | P37: A0091P145 | Q37: AT000AGRANA3 | R37: BF0X9L7 | S37: Mondi Plc | T37: MNDI | U37: G6258S115 | V37: BMWC6P4 | W37: Agrana Beteiligungs | X37: Mondi | AI37: 45068
A38: CUSTOMER | B38: =C38&IF(Q38="",W38,Q38) -> GB00B63H8491EE3100004250 | C38: GB00B63H8491 | D38: =SIGN(VLOOKUP(target_uk!C38,has_scf!$E$2:$F$1366,2,FALSE)) -> 1 | E38: 42991 | F38: CUST-113368073 | G38: 194503576 | H38: 240030 | K38: Y | N38: Harju Elekter Group AS | O38: HAE1T | P38: X3244C107 | Q38: EE3100004250 | R38: 5392070 | S38: Rolls-Royce Holdings Plc | T38: RR | U38: G76225104 | V38: B63H849 | W38: Harju Elekter | X38: Rolls-Royce | Y38: clients | AI38: 44110
A39: CUSTOMER | B39: =C39&IF(Q39="",W39,Q39) -> GB00B63H8491EE3100004250 | C39: GB00B63H8491 | D39: =SIGN(VLOOKUP(target_uk!C39,has_scf!$E$2:$F$1366,2,FALSE)) -> 1 | E39: 44110 | F39: CUST-113368073 | G39: 194503576 | H39: 240030 | K39: Y | N39: Harju Elekter Group AS | O39: HAE1T | P39: X3244C107 | Q39: EE3100004250 | R39: 5392070 | S39: Rolls-Royce Holdings Plc | T39: RR | U39: G76225104 | V39: B63H849 | W39: Harju Elekter | X39: Rolls-Royce | Y39: clients | AI39: 44110
A40: CUSTOMER | B40: =C40&IF(Q40="",W40,Q40) -> GB00B60BWY28FR0000064446 | C40: GB00B60BWY28 | D40: =SIGN(VLOOKUP(target_uk!C40,has_scf!$E$2:$F$1366,2,FALSE)) -> 0 | E40: 43033 | F40: CUST-115202677 | G40: 1922749 | H40: 194524051 | K40: Y | N40: Catering International & Services | O40: ALCIS | P40: F1422H104 | Q40: FR0000064446 | R40: 7172946 | S40: Hummingbird Resources Plc | T40: HUM | U40: G4706Q104 | V40: B60BWY2 | W40: Catering International | X40: Hummingbird | AI40: 44391
...

Sheet source_uk
A1: rel_type | B1: column_4_doublecounting | C1: source_isin | D1: has_scf | E1: start_ | F1: id | G1: source_company_id | H1: target_company_id | I1: subsidiaries | J1: revenue_percent | K1: percent_estimated | L1: source_company_subsidiaries | M1: target_company_subsidiaries | N1: source_name | O1: source_ticker | P1: source_cusip | Q1: source_sedol | R1: target_name | S1: target_ticker | T1: target_cusip | U1: target_isin | V1: target_sedol | W1: source_company_keyword | X1: target_company_keyword | Y1: keyword1 | Z1: keyword2 | AA1: keyword3 | AB1: keyword4 | AC1: keyword5 | AD1: keyword6 | AE1: keyword7 | AF1: keyword8 | AG1: keyword9 | AH1: keyword10 | AI1: end_
A2: SUPPLIER | B2: =C2&IF(U2="",R2,U2) -> GB0006615826Chelverton Asset Management Ltd. | C2: GB0006615826 | D2: =SIGN(VLOOKUP(C2,has_scf!$E$2:$F$1366,2,FALSE)) -> 0 | E2: 42786 | F2: SUPPL-104775748 | G2: 1921493 | H2: 8206680 | K2: Y | N2: Chelverton UK Dividend Trust Plc | O2: SDV | P2: G8185S119 | Q2: 661582 | R2: Chelverton Asset Management Ltd. | W2: Small Companies Dividend Trust | Y2: Investment Manager | AI2: 45211
A3: SUPPLIER | B3: =C3&IF(U3="",R3,U3) -> GB00BSBMW716CH0025238863 | C3: GB00BSBMW716 | D3: =SIGN(VLOOKUP(C3,has_scf!$E$2:$F$1366,2,FALSE)) -> 0 | E3: 42787 | F3: SUPPL-104811647 | G3: 69517152 | H3: 8930788 | K3: Y | N3: Focusrite Plc | O3: TUNE | P3: G3610N108 | Q3: BSBMW71 | R3: KÃ¼hne + Nagel International AG | S3: KNIN | T3: H4673L145 | U3: CH0025238863 | V3: B142S60 | W3: focusrite plc | X3: Kuehne & Nagel | Y3: logistics | AI3: 44161
A4: SUPPLIER | B4: =C4&IF(U4="",R4,U4) -> GB00BSBMW716CH0025238863 | C4: GB00BSBMW716 | D4: =SIGN(VLOOKUP(C4,has_scf!$E$2:$F$1366,2,FALSE)) -> 0 | E4: 44161 | F4: SUPPL-104811647 | G4: 69517152 | H4: 8930788 | K4: Y | N4: Focusrite Plc | O4: TUNE | P4: G3610N108 | Q4: BSBMW71 | R4: KÃ¼hne + Nagel International AG | S4: KNIN | T4: H4673L145 | U4: CH0025238863 | V4: B142S60 | W4: focusrite plc | X4: Kuehne & Nagel | Y4: logistics | AI4: 44161
A5: SUPPLIER | B5: =C5&IF(U5="",R5,U5) -> GB00BSBMW716Gibson Brands, Inc. | C5: GB00BSBMW716 | D5: =SIGN(VLOOKUP(C5,has_scf!$E$2:$F$1366,2,FALSE)) -> 0 | E5: 42787 | F5: SUPPL-104816680 | G5: 69517152 | H5: 9443989 | K5: Y | M5: KRK Systems LLC | N5: Focusrite Plc | O5: TUNE | P5: G3610N108 | Q5: BSBMW71 | R5: Gibson Brands, Inc. | W5: focusrite plc | X5: KRK Systems LLC | Y5: monitors | AI5: 44180
A6: SUPPLIER | B6: =C6&IF(U6="",R6,U6) -> GB00BSBMW716Gibson Brands, Inc. | C6: GB00BSBMW716 | D6: =SIGN(VLOOKUP(C6,has_scf!$E$2:$F$1366,2,FALSE)) -> 0 | E6: 44180 | F6: SUPPL-104816680 | G6: 69517152 | H6: 9443989 | K6: Y | M6: KRK Systems LLC | N6: Focusrite Plc | O6: TUNE | P6: G3610N108 | Q6: BSBMW71 | R6: Gibson Brands, Inc. | W6: focusrite plc | X6: KRK Systems LLC | Y6: monitors | AI6: 44180
A7: SUPPLIER | B7: =C7&IF(U7="",R7,U7) -> GB00BSBMW716Ableton AG | C7: GB00BSBMW716 | D7: =SIGN(VLOOKUP(C7,has_scf!$E$2:$F$1366,2,FALSE)) -> 0 | E7: 42787 | F7: SUPPL-104816806 | G7: 69517152 | H7: 7096310 | K7: Y | N7: Focusrite Plc | O7: TUNE | P7: G3610N108 | Q7: BSBMW71 | R7: Ableton AG | W7: focusrite plc | X7: Ableton | AI7: 44161
A8: SUPPLIER | B8: =C8&IF(U8="",R8,U8) -> GB00BSBMW716Ableton AG | C8: GB00BSBMW716 | D8: =SIGN(VLOOKUP(C8,has_scf!$E$2:$F$1366,2,FALSE)) -> 0 | E8: 44161 | F8: SUPPL-104816806 | G8: 69517152 | H8: 7096310 | K8: Y | N8: Focusrite Plc | O8: TUNE | P8: G3610N108 | Q8: BSBMW71 | R8: Ableton AG | W8: focusrite plc | X8: Ableton | AI8: 44161
A9: SUPPLIER | B9: =C9&IF(U9="",R9,U9) -> GB00BSBMW716Gibson Brands, Inc. | C9: GB00BSBMW716 | D9: =SIGN(VLOOKUP(C9,has_scf!$E$2:$F$1366,2,FALSE)) -> 0 | E9: 42787 | F9: SUPPL-104817198 | G9: 69517152 | H9: 9443989 | K9: Y | M9: Stanton Magnetics Inc | N9: Focusrite Plc | O9: TUNE | P9: G3610N108 | Q9: BSBMW71 | R9: Gibson Brands, Inc. | W9: focusrite plc | X9: Stanton Magnetics | AI9: 44180
A10: SUPPLIER | B10: =C10&IF(U10="",R10,U10) -> GB00BSBMW716Gibson Brands, Inc. | C10: GB00BSBMW716 | D10: =SIGN(VLOOKUP(C10,has_scf!$E$2:$F$1366,2,FALSE)) -> 0 | E10: 44180 | F10: SUPPL-104817198 | G10: 69517152 | H10: 9443989 | K10: Y | M10: Stanton Magnetics Inc | N10: Focusrite Plc | O10: TUNE | P10: G3610N108 | Q10: BSBMW71 | R10: Gibson Brands, Inc. | W10: focusrite plc | X10: Stanton Magnetics | AI10: 44180
A11: SUPPLIER | B11: =C11&IF(U11="",R11,U11) -> GB00BSBMW716Gibson Brands, Inc. | C11: GB00BSBMW716 | D11: =SIGN(VLOOKUP(C11,has_scf!$E$2:$F$1366,2,FALSE)) -> 0 | E11: 42787 | F11: SUPPL-104817256 | G11: 69517152 | H11: 9443989 | K11: Y | M11: Cerwin-Vega Inc | N11: Focusrite Plc | O11: TUNE | P11: G3610N108 | Q11: BSBMW71 | R11: Gibson Brands, Inc. | W11: focusrite plc | X11: Cerwin-Vega | AI11: 44180
A12: SUPPLIER | B12: =C12&IF(U12="",R12,U12) -> GB00BSBMW716Gibson Brands, Inc. | C12: GB00BSBMW716 | D12: =SIGN(VLOOKUP(C12,has_scf!$E$2:$F$1366,2,FALSE)) -> 0 | E12: 44180 | F12: SUPPL-104817256 | G12: 69517152 | H12: 9443989 | K12: Y | M12: Cerwin-Vega Inc | N12: Focusrite Plc | O12: TUNE | P12: G3610N108 | Q12: BSBMW71 | R12: Gibson Brands, Inc. | W12: focusrite plc | X12: Cerwin-Vega | AI12: 44180
A13: SUPPLIER | B13: =C13&IF(U13="",R13,U13) -> GB00BSBMW716 | C13: GB00BSBMW716 | D13: =SIGN(VLOOKUP(C13,has_scf!$E$2:$F$1366,2,FALSE)) -> 0 | E13: 42796 | F13: SUPPL-105319671 | G13: 69517152 | H13: 105319400 | K13: Y | N13: Focusrite Plc | O13: TUNE | P13: G3610N108 | Q13: BSBMW71 | W13: focusrite plc | X13: sE Electronics International | Y13: Distribution | AI13: 45664
A14: SUPPLIER | B14: =C14&IF(U14="",R14,U14) -> GB00BQFH6320Government of France | C14: GB00BQFH6320 | D14: =SIGN(VLOOKUP(C14,has_scf!$E$2:$F$1366,2,FALSE)) -> 0 | E14: 42948 | F14: SUPPL-111887319 | G14: 85326175 | H14: 228636 | K14: Y | M14: City of Cannes | N14: Ascential Plc | O14: ASCL | P14: G0519H166 | Q14: BQFH632 | R14: Government of France | W14: Ascential | X14: City of Cannes | Y14: venue | AI14: 43952
A15: SUPPLIER | B15: =C15&IF(U15="",R15,U15) -> GB00BQFH6320Government of France | C15: GB00BQFH6320 | D15: =SIGN(VLOOKUP(C15,has_scf!$E$2:$F$1366,2,FALSE)) -> 0 | E15: 43952 | F15: SUPPL-111887319 | G15: 85326175 | H15: 228636 | K15: Y | M15: City of Cannes | N15: Ascential Plc | O15: ASCL | P15: G0519H166 | Q15: BQFH632 | R15: Government of France | W15: Ascential | X15: City of Cannes | Y15: venue | AI15: 43952
A16: SUPPLIER | B16: =C16&IF(U16="",R16,U16) -> GB00BYQ94H38The University of Nottingham | C16: GB00BYQ94H38 | D16: =SIGN(VLOOKUP(C16,has_scf!$E$2:$F$1366,2,FALSE)) -> 0 | E16: 42949 | F16: SUPPL-111965556 | G16: 89910202 | H16: 245376 | K16: Y | N16: Oncimmune Holdings Plc | O16: ONC | P16: G6750T108 | Q16: BYQ94H3 | R16: The University of Nottingham | W16: Oncimmune | X16: University of Nottingham | Y16: facilities | Z16: research | AI16: 45406
A17: SUPPLIER | B17: =C17&IF(U17="",R17,U17) -> GB0059337583 | C17: GB0059337583 | D17: =SIGN(VLOOKUP(C17,has_scf!$E$2:$F$1366,2,FALSE)) -> 0 | E17: 43075 | F17: SUPPL-117614041 | G17: 194516577 | H17: 1915 | K17: Y | N17: Deltex Medical Group Plc | O17: DEMG | P17: G2709P107 | Q17: 3103865 | W17: Deltex Medical | X17: CAS Medical Systems | Y17: UK | Z17: cerebral oximetry monitoring market | AA17: exclusive distribution | AB17: CASMED | AC17: FORE-SIGHT cerebral oximeter monitors | AD17: Ireland | AI17: 44032
A18: SUPPLIER | B18: =C18&IF(U18="",R18,U18) -> GB0059337583 | C18: GB0059337583 | D18: =SIGN(VLOOKUP(C18,has_scf!$E$2:$F$1366,2,FALSE)) -> 0 | E18: 44032 | F18: SUPPL-117614041 | G18: 194516577 | H18: 1915 | K18: Y | N18: Deltex Medical Group Plc | O18: DEMG | P18: G2709P107 | Q18: 3103865 | W18: Deltex Medical | X18: CAS Medical Systems | Y18: UK | Z18: cerebral oximetry monitoring market | AA18: exclusive distribution | AB18: CASMED | AC18: FORE-SIGHT cerebral oximeter monitors | AD18: Ireland | AI18: 44032
A19: SUPPLIER | B19: =C19&IF(U19="",R19,U19) -> GB00B7KR2P84DE0005552004 | C19: GB00B7KR2P84 | D19: =SIGN(VLOOKUP(C19,has_scf!$E$2:$F$1366,2,FALSE)) -> 0 | E19: 43488 | F19: SUPPL-117980002 | G19: 1634656 | H19: 1557283 | K19: Y | M19: DHL Express | N19: easyJet Plc | O19: EZJ | P19: G3030S109 | Q19: B7KR2P8 | R19: Deutsche Post AG | S19: DHL | T19: D19225107 | U19: DE0005552004 | V19: 4617859 | W19: easyJet | X19: Deutsche Post | Y19: Ground Handling | AI19: 45637
A20: SUPPLIER | B20: =C20&IF(U20="",R20,U20) -> GB00BY7R8K77GB00BP9LHF23 | C20: GB00BY7R8K77 | D20: =SIGN(VLOOKUP(C20,has_scf!$E$2:$F$1366,2,FALSE)) -> 0 | E20: 43809 | F20: SUPPL-104128606 | G20: 82444487 | H20: 1732173 | K20: Y | N20: Schroder European Real Estate Investment Trust Plc | O20: SERE | P20: G7856Y108 | Q20: BY7R8K7 | R20: Schroders Plc | S20: SDR | T20: G78602144 | U20: GB00BP9LHF23 | V20: BP9LHF2 | W20: schroder european real estate investment trust plc | X20: Schroders | Y20: Substantial share interests | AI20: 45405
A21: SUPPLIER | B21: =C21&IF(U21="",R21,U21) -> GB00BSB7BS06 | C21: GB00BSB7BS06 | D21: =SIGN(VLOOKUP(C21,has_scf!$E$2:$F$1366,2,FALSE)) -> 0 | E21: 43565 | F21: SUPPL-104169882 | G21: 1832424 | H21: 9556323 | K21: Y | L21: Evans Halshaw Ltd. | M21: Automobiles Citroen SA | N21: Pinewood Technologies Group Plc | O21: PINE | P21: G6986L192 | Q21: BSB7BS0 | W21: Evans Halshaw | X21: Automobiles Citroen | AI21: 44216
A22: SUPPLIER | B22: =C22&IF(U22="",R22,U22) -> GB00BSB7BS06 | C22: GB00BSB7BS06 | D22: =SIGN(VLOOKUP(C22,has_scf!$E$2:$F$1366,2,FALSE)) -> 0 | E22: 44216 | F22: SUPPL-104169882 | G22: 1832424 | H22: 9556323 | K22: Y | L22: Evans Halshaw Ltd. | M22: Automobiles Citroen SA | N22: Pinewood Technologies Group Plc | O22: PINE | P22: G6986L192 | Q22: BSB7BS0 | W22: Evans Halshaw | X22: Automobiles Citroen | AI22: 44216
A23: SUPPLIER | B23: =C23&IF(U23="",R23,U23) -> GB00B0744B38 | C23: GB00B0744B38 | D23: =SIGN(VLOOKUP(C23,has_scf!$E$2:$F$1366,2,FALSE)) -> 0 | E23: 42886 | F23: SUPPL-109397977 | G23: 1302 | H23: 8453544 | K23: Y | N23: Bunzl Plc | O23: BNZL | P23: G16968110 | Q23: B0744B3 | W23: Bunzl | Y23: Global Sourcing | AI23: 44300
A24: SUPPLIER | B24: =C24&IF(U24="",R24,U24) -> GB0031429219JE00BYPZJM29 | C24: GB0031429219 | D24: =SIGN(VLOOKUP(C24,has_scf!$E$2:$F$1366,2,FALSE)) -> 0 | E24: 43243 | F24: SUPPL-109459191 | G24: 1921502 | H24: 109351491 | K24: Y | M24: Janus Henderson Investors | N24: Law Debenture Corp. Plc | O24: LWDB | P24: G53900125 | Q24: 3142921 | R24: Janus Henderson Group Plc | S24: JHG | T24: G4474Y214 | U24: JE00BYPZJM29 | V24: BYPZJQ6 | W24: The Law Debenture | X24: Janus Henderson Group | Y24: Investment manager | AI24: 44281
A25: SUPPLIER | B25: =C25&IF(U25="",R25,U25) -> GB00BN4NDR39JE00BYPZJM29 | C25: GB00BN4NDR39 | D25: =SIGN(VLOOKUP(C25,has_scf!$E$2:$F$1366,2,FALSE)) -> 0 | E25: 42887 | F25: SUPPL-109459198 | G25: 1921762 | H25: 109351491 | K25: Y | M25: Henderson Investment Funds Limited | N25: The Bankers Investment Trust Plc | O25: BNKR | P25: G07476123 | Q25: BN4NDR3 | R25: Janus Henderson Group Plc | S25: JHG | T25: G4474Y214 | U25: JE00BYPZJM29 | V25: BYPZJQ6 | W25: Bankers Investment Trust | X25: Henderson Investment Funds Limited | Y25: Alternative Investment Fund Manager | Z25: AIFMD | AA25: HIFL | AI25: 44950
A26: SUPPLIER | B26: =C26&IF(U26="",R26,U26) -> GB0001990497JE00BYPZJM29 | C26: GB0001990497 | D26: =SIGN(VLOOKUP(C26,has_scf!$E$2:$F$1366,2,FALSE)) -> 0 | E26: 43049 | F26: SUPPL-109459206 | G26: 16001353 | H26: 109351491 | K26: Y | M26: Henderson Investment Funds Limited | N26: The City of London Investment Trust Plc | O26: CTY | P26: G90260103 | Q26: 199049 | R26: Janus Henderson Group Plc | S26: JHG | T26: G4474Y214 | U26: JE00BYPZJM29 | V26: BYPZJQ6 | W26: The City of London Investment Trust PLC | X26: Janus Henderson Fund Management | Y26: Alternative Investment Fund Manager | AI26: 45937
A27: SUPPLIER | B27: =C27&IF(U27="",R27,U27) -> GB00BLSNGB01JE00BYPZJM29 | C27: GB00BLSNGB01 | D27: =SIGN(VLOOKUP(C27,has_scf!$E$2:$F$1366,2,FALSE)) -> 0 | E27: 42887 | F27: SUPPL-109459244 | G27: 16001008 | H27: 109351491 | K27: Y | M27: Henderson Investment Funds Limited | N27: Henderson European Trust Plc | O27: HET | P27: G4464P116 | Q27: BLSNGB0 | R27: Janus Henderson Group Plc | S27: JHG | T27: G4474Y214 | U27: JE00BYPZJM29 | V27: BYPZJQ6 | W27: Henderson | X27: Henderson Investment Funds Limited | Y27: Alternative Investment Fund Manager | AI27: 45405
A28: SUPPLIER | B28: =C28&IF(U28="",R28,U28) -> GB00BNXGHS27JE00BYPZJM29 | C28: GB00BNXGHS27 | D28: =SIGN(VLOOKUP(C28,has_scf!$E$2:$F$1366,2,FALSE)) -> 0 | E28: 42887 | F28: SUPPL-109459248 | G28: 1921507 | H28: 109351491 | K28: Y | M28: Henderson Investment Funds Limited | N28: Lowland Investment Co. Plc | O28: LWI | P28: G56784112 | Q28: BNXGHS2 | R28: Janus Henderson Group Plc | S28: JHG | T28: G4474Y214 | U28: JE00BYPZJM29 | V28: BYPZJQ6 | W28: Lowland Investment | X28: Janus Henderson Fund Management | Y28: Alternative Investment Fund Manager | AI28: 44925
A29: SUPPLIER | B29: =C29&IF(U29="",R29,U29) -> GB0009580571JE00BYPZJM29 | C29: GB0009580571 | D29: =SIGN(VLOOKUP(C29,has_scf!$E$2:$F$1366,2,FALSE)) -> 0 | E29: 42887 | F29: SUPPL-109459266 | G29: 1921688 | H29: 109351491 | K29: Y | M29: Henderson Investment Funds Limited | N29: Henderson High Income Trust Plc | O29: HHI | P29: G4464B109 | Q29: 958057 | R29: Janus Henderson Group Plc | S29: JHG | T29: G4474Y214 | U29: JE00BYPZJM29 | V29: BYPZJQ6 | W29: Henderson High Income Trust | X29: Henderson Investment Funds Limited | Y29: Alternative Investment Fund Manager | AI29: 44361
A30: SUPPLIER | B30: =C30&IF(U30="",R30,U30) -> GB00B0LCW083FI0009014377 | C30: GB00B0LCW083 | D30: =SIGN(VLOOKUP(C30,has_scf!$E$2:$F$1366,2,FALSE)) -> 0 | E30: 43937 | F30: SUPPL-109655342 | G30: 1832305 | H30: 22440304 | K30: Y | N30: Hikma Pharmaceuticals Plc | O30: HIK | P30: G4576K104 | Q30: B0LCW08 | R30: Orion Oyj | S30: ORNBV | T30: X6002Y112 | U30: FI0009014377 | V30: B17NY40 | W30: Hikma Pharmaceuticals | X30: Orion | Y30: Bufomix easyhaler | AI30: 45006
A31: SUPPLIER | B31: =C31&IF(U31="",R31,U31) -> GB00BV9FP302Vidyo, Inc. | C31: GB00BV9FP302 | D31: =SIGN(VLOOKUP(C31,has_scf!$E$2:$F$1366,2,FALSE)) -> 1 | E31: 42895 | F31: SUPPL-109778656 | G31: 1625707 | H31: 26531675 | K31: Y | N31: Computacenter Plc | O31: CCC | P31: G23356150 | Q31: BV9FP30 | R31: Vidyo, Inc. | W31: Computacenter | X31: Vidyo | Y31: Conferencing solutions | AI31: 44790
A32: SUPPLIER | B32: =C32&IF(U32="",R32,U32) -> GB00BM8Q5M07Sportswear Co. SpA | C32: GB00BM8Q5M07 | D32: =SIGN(VLOOKUP(C32,has_scf!$E$2:$F$1366,2,FALSE)) -> 0 | E32: 43263 | F32: SUPPL-113829538 | G32: 1832342 | H32: 112088400 | K32: Y | L32: Tessuti Ltd. | N32: JD Sports Fashion Plc | O32: JD | P32: G5144Y120 | Q32: BM8Q5M0 | R32: Sportswear Co. SpA | W32: Tessuti | X32: sportswear spa | Y32: Stone Island | Z32: footwear | AA32: accessories | AB32: apparel | AI32: 44820
A33: SUPPLIER | B33: =C33&IF(U33="",R33,U33) -> GB00B1GK4645DE0007100000 | C33: GB00B1GK4645 | D33: =SIGN(VLOOKUP(C33,has_scf!$E$2:$F$1366,2,FALSE)) -> 0 | E33: 43027 | F33: SUPPL-114921373 | G33: 194521070 | H33: 19337 | K33: Y | M33: Mercedes-Benz | N33: Vertu Motors Plc | O33: VTU | P33: G9337V109 | Q33: B1GK464 | R33: Mercedes-Benz Group AG | S33: MBG | T33: D1668R123 | U33: DE0007100000 | V33: 5529027 | W33: Vertu Motors | X33: Mercedez-Benz | AI33: 44780
A34: SUPPLIER | B34: =C34&IF(U34="",R34,U34) -> GB00B1GK4645JP3633400001 | C34: GB00B1GK4645 | D34: =SIGN(VLOOKUP(C34,has_scf!$E$2:$F$1366,2,FALSE)) -> 0 | E34: 43027 | F34: SUPPL-114921937 | G34: 194521070 | H34: 10260 | K34: Y | N34: Vertu Motors Plc | O34: VTU | P34: G9337V109 | Q34: B1GK464 | R34: Toyota Motor Corp. | S34: 7203 | T34: J92676113 | U34: JP3633400001 | V34: 6900643 | W34: Vertu Motors | X34: Toyota | AI34: 44780
A35: SUPPLIER | B35: =C35&IF(U35="",R35,U35) -> GB00B1GK4645DE0006757008 | C35: GB00B1GK4645 | D35: =SIGN(VLOOKUP(C35,has_scf!$E$2:$F$1366,2,FALSE)) -> 0 | E35: 43027 | F35: SUPPL-114922954 | G35: 194521070 | H35: 19299200 | K35: Y | N35: Vertu Motors Plc | O35: VTU | P35: G9337V109 | Q35: B1GK464 | R35: AUDI AG | S35: NSU | T35: D04312100 | U35: DE0006757008 | V35: 5761498 | W35: Vertu Motors | X35: Audi | AI35: 44780
A36: SUPPLIER | B36: =C36&IF(U36="",R36,U36) -> GB00BCRX1J15FR0010411983 | C36: GB00BCRX1J15 | D36: =SIGN(VLOOKUP(C36,has_scf!$E$2:$F$1366,2,FALSE)) -> 0 | E36: 43028 | F36: SUPPL-115039002 | G36: 89242004 | H36: 9083 | K36: Y | M36: SCOR Life Global Life (UK Branch). | N36: Just Group Plc | O36: JUST | P36: G9331B109 | Q36: BCRX1J1 | R36: SCOR SE | S36: SCR | T36: F15561677 | U36: FR0010411983 | V36: B1LB9P6 | W36: jrp group plc | X36: SCOR | Y36: reinsurers | AI36: 43958
A37: SUPPLIER | B37: =C37&IF(U37="",R37,U37) -> GB00BCRX1J15FR0010411983 | C37: GB00BCRX1J15 | D37: =SIGN(VLOOKUP(C37,has_scf!$E$2:$F$1366,2,FALSE)) -> 0 | E37: 43958 | F37: SUPPL-115039002 | G37: 89242004 | H37: 9083 | K37: Y | M37: SCOR Life Global Life (UK Branch). | N37: Just Group Plc | O37: JUST | P37: G9331B109 | Q37: BCRX1J1 | R37: SCOR SE | S37: SCR | T37: F15561677 | U37: FR0010411983 | V37: B1LB9P6 | W37: jrp group plc | X37: SCOR | Y37: reinsurers | AI37: 43958
A38: SUPPLIER | B38: =C38&IF(U38="",R38,U38) -> GB00BCRX1J15 | C38: GB00BCRX1J15 | D38: =SIGN(VLOOKUP(C38,has_scf!$E$2:$F$1366,2,FALSE)) -> 0 | E38: 43028 | F38: SUPPL-115039160 | G38: 89242004 | H38: 6266508 | K38: Y | N38: Just Group Plc | O38: JUST | P38: G9331B109 | Q38: BCRX1J1 | W38: jrp group plc | Y38: Reinsurers | AI38: 43958
A39: SUPPLIER | B39: =C39&IF(U39="",R39,U39) -> GB00BCRX1J15 | C39: GB00BCRX1J15 | D39: =SIGN(VLOOKUP(C39,has_scf!$E$2:$F$1366,2,FALSE)) -> 0 | E39: 43958 | F39: SUPPL-115039160 | G39: 89242004 | H39: 6266508 | K39: Y | N39: Just Group Plc | O39: JUST | P39: G9331B109 | Q39: BCRX1J1 | W39: jrp group plc | Y39: Reinsurers | AI39: 43958
A40: SUPPLIER | B40: =C40&IF(U40="",R40,U40) -> GB00BCRX1J15US0846707026 | C40: GB00BCRX1J15 | D40: =SIGN(VLOOKUP(C40,has_scf!$E$2:$F$1366,2,FALSE)) -> 0 | E40: 43028 | F40: SUPPL-115039199 | G40: 89242004 | H40: 1319 | K40: Y | M40: General Reinsurance AG (London branch) | N40: Just Group Plc | O40: JUST | P40: G9331B109 | Q40: BCRX1J1 | R40: Berkshire Hathaway, Inc. | S40: BRK.B | T40: 84670702 | U40: US0846707026 | V40: 2073390 | W40: jrp group plc | X40: General Reinsurance AG (London branch), | Y40: Reinsurers | AI40: 43958
...

Sheet doublecounting
C2: in target customer relationship | D2: in source supplier relationships | E2: doublecounting | F2: in target with scf | G2: in source with scf | H2: doublecounting
B3: GB00BK9RKT01SE0000407991 | C3: =COUNTIF(target_uk!$B$2:$B$3030,doublecounting!B3) -> 2 | D3: =COUNTIF(source_uk!$B$2:$B$2603,doublecounting!B3) -> 0 | E3: =SIGN(C3*D3) -> 0 | F3: =COUNTIFS(target_uk!$B$2:$B$3030,doublecounting!B3,target_uk!$D$2:$D$3030,1) -> 2 | G3: =COUNTIFS(source_uk!$B$2:$B$2603,doublecounting!B3,source_uk!$D$2:$D$2603,1) -> 0 | H3: =SIGN(F3*G3) -> 0
B4: GB00B3MBS747US84763R1014 | C4: =COUNTIF(target_uk!$B$2:$B$3030,doublecounting!B4) -> 1 | D4: =COUNTIF(source_uk!$B$2:$B$2603,doublecounting!B4) -> 0 | E4: =SIGN(C4*D4) -> 0 | F4: =COUNTIFS(target_uk!$B$2:$B$3030,doublecounting!B4,target_uk!$D$2:$D$3030,1) -> 0 | G4: =COUNTIFS(source_uk!$B$2:$B$2603,doublecounting!B4,source_uk!$D$2:$D$2603,1) -> 0 | H4: =SIGN(F4*G4) -> 0
B5: GB00B012TP20US84763R1014 | C5: =COUNTIF(target_uk!$B$2:$B$3030,doublecounting!B5) -> 1 | D5: =COUNTIF(source_uk!$B$2:$B$2603,doublecounting!B5) -> 0 | E5: =SIGN(C5*D5) -> 0 | F5: =COUNTIFS(target_uk!$B$2:$B$3030,doublecounting!B5,target_uk!$D$2:$D$3030,1) -> 0 | G5: =COUNTIFS(source_uk!$B$2:$B$2603,doublecounting!B5,source_uk!$D$2:$D$2603,1) -> 0 | H5: =SIGN(F5*G5) -> 0
B6: GB00BRJQ8J25GB0009422543 | C6: =COUNTIF(target_uk!$B$2:$B$3030,doublecounting!B6) -> 5 | D6: =COUNTIF(source_uk!$B$2:$B$2603,doublecounting!B6) -> 0 | E6: =SIGN(C6*D6) -> 0 | F6: =COUNTIFS(target_uk!$B$2:$B$3030,doublecounting!B6,target_uk!$D$2:$D$3030,1) -> 0 | G6: =COUNTIFS(source_uk!$B$2:$B$2603,doublecounting!B6,source_uk!$D$2:$D$2603,1) -> 0 | H6: =SIGN(F6*G6) -> 0
B7: GB00B0744B38US6097201072 | C7: =COUNTIF(target_uk!$B$2:$B$3030,doublecounting!B7) -> 3 | D7: =COUNTIF(source_uk!$B$2:$B$2603,doublecounting!B7) -> 0 | E7: =SIGN(C7*D7) -> 0 | F7: =COUNTIFS(target_uk!$B$2:$B$3030,doublecounting!B7,target_uk!$D$2:$D$3030,1) -> 0 | G7: =COUNTIFS(source_uk!$B$2:$B$2603,doublecounting!B7,source_uk!$D$2:$D$2603,1) -> 0 | H7: =SIGN(F7*G7) -> 0
B8: GB00B1L5QH97MT0000780107 | C8: =COUNTIF(target_uk!$B$2:$B$3030,doublecounting!B8) -> 2 | D8: =COUNTIF(source_uk!$B$2:$B$2603,doublecounting!B8) -> 0 | E8: =SIGN(C8*D8) -> 0 | F8: =COUNTIFS(target_uk!$B$2:$B$3030,doublecounting!B8,target_uk!$D$2:$D$3030,1) -> 0 | G8: =COUNTIFS(source_uk!$B$2:$B$2603,doublecounting!B8,source_uk!$D$2:$D$2603,1) -> 0 | H8: =SIGN(F8*G8) -> 0
B9: GB0031274896LK0080N00008 | C9: =COUNTIF(target_uk!$B$2:$B$3030,doublecounting!B9) -> 2 | D9: =COUNTIF(source_uk!$B$2:$B$2603,doublecounting!B9) -> 0 | E9: =SIGN(C9*D9) -> 0 | F9: =COUNTIFS(target_uk!$B$2:$B$3030,doublecounting!B9,target_uk!$D$2:$D$3030,1) -> 2 | G9: =COUNTIFS(source_uk!$B$2:$B$2603,doublecounting!B9,source_uk!$D$2:$D$2603,1) -> 0 | H9: =SIGN(F9*G9) -> 0
B10: GB0032089863LK0080N00008 | C10: =COUNTIF(target_uk!$B$2:$B$3030,doublecounting!B10) -> 2 | D10: =COUNTIF(source_uk!$B$2:$B$2603,doublecounting!B10) -> 0 | E10: =SIGN(C10*D10) -> 0 | F10: =COUNTIFS(target_uk!$B$2:$B$3030,doublecounting!B10,target_uk!$D$2:$D$3030,1) -> 0 | G10: =COUNTIFS(source_uk!$B$2:$B$2603,doublecounting!B10,source_uk!$D$2:$D$2603,1) -> 0 | H10: =SIGN(F10*G10) -> 0
B11: GB00B63H8491NO0003064107 | C11: =COUNTIF(target_uk!$B$2:$B$3030,doublecounting!B11) -> 1 | D11: =COUNTIF(source_uk!$B$2:$B$2603,doublecounting!B11) -> 0 | E11: =SIGN(C11*D11) -> 0 | F11: =COUNTIFS(target_uk!$B$2:$B$3030,doublecounting!B11,target_uk!$D$2:$D$3030,1) -> 1 | G11: =COUNTIFS(source_uk!$B$2:$B$2603,doublecounting!B11,source_uk!$D$2:$D$2603,1) -> 0 | H11: =SIGN(F11*G11) -> 0
B12: GB0007325078L. G. Balakrishnan & Brothers | C12: =COUNTIF(target_uk!$B$2:$B$3030,doublecounting!B12) -> 2 | D12: =COUNTIF(source_uk!$B$2:$B$2603,doublecounting!B12) -> 0 | E12: =SIGN(C12*D12) -> 0 | F12: =COUNTIFS(target_uk!$B$2:$B$3030,doublecounting!B12,target_uk!$D$2:$D$3030,1) -> 0 | G12: =COUNTIFS(source_uk!$B$2:$B$2603,doublecounting!B12,source_uk!$D$2:$D$2603,1) -> 0 | H12: =SIGN(F12*G12) -> 0
B13: GB00BJVH7905Summit Utica | C13: =COUNTIF(target_uk!$B$2:$B$3030,doublecounting!B13) -> 1 | D13: =COUNTIF(source_uk!$B$2:$B$2603,doublecounting!B13) -> 0 | E13: =SIGN(C13*D13) -> 0 | F13: =COUNTIFS(target_uk!$B$2:$B$3030,doublecounting!B13,target_uk!$D$2:$D$3030,1) -> 0 | G13: =COUNTIFS(source_uk!$B$2:$B$2603,doublecounting!B13,source_uk!$D$2:$D$2603,1) -> 0 | H13: =SIGN(F13*G13) -> 0
B14: GB0007188757CLP6877L1036 | C14: =COUNTIF(target_uk!$B$2:$B$3030,doublecounting!B14) -> 1 | D14: =COUNTIF(source_uk!$B$2:$B$2603,doublecounting!B14) -> 0 | E14: =SIGN(C14*D14) -> 0 | F14: =COUNTIFS(target_uk!$B$2:$B$3030,doublecounting!B14,target_uk!$D$2:$D$3030,1) -> 1 | G14: =COUNTIFS(source_uk!$B$2:$B$2603,doublecounting!B14,source_uk!$D$2:$D$2603,1) -> 0 | H14: =SIGN(F14*G14) -> 0
... B3579: GB0003463402Jupiter Investment Management Group Ltd. | C3579: =COUNTIF(target_uk!$B$2:$B$3030,doublecounting!B3579) -> 0 | D3579: =COUNTIF(source_uk!$B$2:$B$2603,doublecounting!B3579) -> 2 | E3579: =SIGN(C3579*D3579) -> 0 | F3579: =COUNTIFS(target_uk!$B$2:$B$3030,doublecounting!B3579,target_uk!$D$2:$D$3030,1) -> 0 | G3579: =COUNTIFS(source_uk!$B$2:$B$2603,doublecounting!B3579,source_uk!$D$2:$D$2603,1) -> 0 | H3579: =SIGN(F3579*G3579) -> 0
